В Go нет исключений (exception) в том виде, как они реализованы в других языках программирования, таких как Java, Python или C++. Вместо этого Go использует более простой механизм обработки ошибок, который основан на возвращаемых значениях и явной проверке ошибок.

## Как обрабатываются ошибки в Go:
1. Возврат ошибки: В Go функции обычно возвращают значение ошибки в качестве последнего значения. Это значение ошибки обычно проверяется сразу после вызова функции.

2. panic и recover: Хотя Go не имеет исключений в классическом понимании, механизм panic и recover позволяет реализовать нечто похожее на исключения. panic вызывает прерывание текущего выполнения функции и передает управление в ближайшую обработку с помощью recover, но это используется в редких случаях, когда происходит необратимая ошибка.

### Пример обработки ошибок с возвратом значения ошибки:
```go
package main

import (
    "errors"
    "fmt"
)

func divide(a, b int) (int, error) {
    if b == 0 {
        // Возвращаем ошибку, если деление на ноль
        return 0, errors.New("деление на ноль")
    }
    return a / b, nil
}

func main() {
    result, err := divide(10, 0)
    if err != nil {
        // Обработка ошибки
        fmt.Println("Ошибка:", err)
    } else {
        // Если ошибки нет
        fmt.Println("Результат:", result)
    }
}
```
#### В этом примере:

- Функция divide возвращает два значения: результат деления и ошибку.
- Ошибка проверяется в main и обрабатывается соответствующим образом.

### panic и recover:
1. panic — это способ вызвать "необработанную ошибку", которая прерывает выполнение программы. Обычно используется для критических ошибок, которые невозможно восстановить или обработать (например, ошибка в логике программы).

2. recover — используется для перехвата и обработки паники, чтобы предотвратить аварийное завершение программы.

#### Пример с panic и recover:

```go
package main

import "fmt"

func mayPanic() {
    panic("что-то пошло не так")
}

func safeCall() {
    defer func() {
        if r := recover(); r != nil {
            fmt.Println("Паника перехвачена:", r)
        }
    }()

    mayPanic()
}

func main() {
    fmt.Println("До паники")
    safeCall() // Программа не завершится аварийно благодаря recover
    fmt.Println("После паники")
}
```
### Объяснение:
- В функции mayPanic вызывается panic, который прерывает выполнение.
- В функции safeCall используется defer для отложенного вызова, и внутри этого отложенного вызова проверяется, была ли паника с помощью recover.
- recover предотвращает аварийное завершение программы и позволяет выполнить код после паники.
- 
### Резюме:
- Исключения в Go нет, вместо этого используется возврат ошибок через возвращаемые значения.
- panic позволяет создавать аварийные остановки программы, но рекомендуется использовать его для необычных, критичных ситуаций.
- recover позволяет перехватить панику и восстановить выполнение программы.

Таким образом, Go придерживается принципа "простота и явность", где обработка ошибок — это явный процесс, а не автоматический механизм, как исключения в других языках.